<?xml version="1.0"?>
<robot name="auto_quad">

    <!-- Odometry -->
    <link name="odom_link"/>
    <joint name="odom_join" type="fixed">
        <parent link="base_link"/>
        <child link="odom_link"/>
        <origin xyz="0 0 0" rpy="0 0 0"/>
    </joint>

    <!-- ################################################################################
         #################################### Frame #####################################
         ################################################################################ -->

    <link name="base_link">
        <!-- <inertial>
            <mass value="1.0"/>
            <origin xyz="0 0 0" rpy="0 0 0"/>
            <inertia ixx="0.1" ixy="0.0" ixz="0.0" iyy="0.1" iyz="0.0" izz="0.1"/>
        </inertial> -->
        <visual>
            <origin xyz="0 0 0" rpy="1.5708 0 0"/>
            <geometry>
                 <mesh filename="package://auto_quad_description/meshes/quadcopter_frame.stl" scale="0.01 0.01 0.01"/>
            </geometry>
            <material name="blue">
            <color rgba="0 0 0.8 1"/>
            </material>
        </visual>
        <collision>
            <origin xyz="0 0 0" rpy="1.5708 0 0"/>
            <geometry>
                 <mesh filename="package://auto_quad_description/meshes/quadcopter_frame.stl" scale="0.01 0.01 0.01"/>
            </geometry>
        </collision>
    </link>


    <!-- ################################################################################
         #################################### Motors ####################################
         ################################################################################ -->

    <!-- Front Left Motor -->
    <link name="front_left_motor">
    <visual>
        <origin xyz="0 0 0" rpy="0 0 0"/> <!-- Adjust xyz for position -->
        <geometry>
        <mesh filename="package://auto_quad_description/meshes/motor.stl" scale="0.01 0.01 0.01"/>
        </geometry>
        <material name="silver">
        <color rgba="0.8 0.8 0.8 1"/>
        </material>
    </visual>
    <collision>
        <origin xyz="0 0 0" rpy="0 0 0"/> <!-- Adjust xyz for position -->
        <geometry>
        <mesh filename="package://auto_quad_description/meshes/motor.stl" scale="0.01 0.01 0.01"/>
        </geometry>
    </collision>
    </link>

    <joint name="front_left_motor_joint" type="fixed">
    <parent link="base_link"/>
    <child link="front_left_motor"/>
    <origin xyz="1.58 1.58 0.18" rpy="0 0 0"/> <!-- Adjust xyz for position -->
    </joint>

    <!-- Front Right Motor -->
    <link name="front_right_motor">
    <visual>
        <geometry>
        <mesh filename="package://auto_quad_description/meshes/motor.stl" scale="0.01 0.01 0.01"/>
        </geometry>
        <material name="silver">
        <color rgba="0.8 0.8 0.8 1"/>
        </material>
    </visual>
    <collision>
        <geometry>
        <mesh filename="package://auto_quad_description/meshes/motor.stl" scale="0.01 0.01 0.01"/>
        </geometry>
    </collision>
    </link>

    <joint name="front_right_motor_joint" type="fixed">
    <parent link="base_link"/>
    <child link="front_right_motor"/>
    <origin xyz="1.58 -1.58 0.18" rpy="0 0 0"/> <!-- Adjust xyz for position -->
    </joint>

    <!-- Back Left Motor -->
    <link name="back_left_motor">
    <visual>
        <geometry>
        <mesh filename="package://auto_quad_description/meshes/motor.stl" scale="0.01 0.01 0.01"/>
        </geometry>
        <material name="silver">
        <color rgba="0.8 0.8 0.8 1"/>
        </material>
    </visual>
    <collision>
       <geometry>
        <mesh filename="package://auto_quad_description/meshes/motor.stl" scale="0.01 0.01 0.01"/>
        </geometry>
    </collision>
    </link>

    <joint name="back_left_motor_joint" type="fixed">
    <parent link="base_link"/>
    <child link="back_left_motor"/>
    <origin xyz="-1.58 1.58 0.18" rpy="0 0 0"/> <!-- Adjust xyz for position -->
    </joint>

    <!-- Back Right Motor -->
    <link name="back_right_motor">
    <visual>
        <geometry>
        <mesh filename="package://auto_quad_description/meshes/motor.stl" scale="0.01 0.01 0.01"/>
        </geometry>
        <material name="silver">
        <color rgba="0.8 0.8 0.8 1"/>
        </material>
    </visual>
    <collision>
        <geometry>
        <mesh filename="package://auto_quad_description/meshes/motor.stl" scale="0.01 0.01 0.01"/>
        </geometry>
    </collision>
    </link>

    <joint name="back_right_motor_joint" type="fixed">
    <parent link="base_link"/>
    <child link="back_right_motor"/>
    <origin xyz="-1.58 -1.58 0.18" rpy="0 0 0"/> <!-- Adjust xyz for position -->
    </joint>


    <!-- ################################################################################
         ################################## Propellers ##################################
         ################################################################################ -->

    <!-- Front Left Propeller -->
    <link name="front_left_propeller">
    <visual>
        <origin xyz="-0.305 1.2275 0" rpy="1.5708 0 0"/>
        <geometry>
        <mesh filename="package://auto_quad_description/meshes/propeller.stl" scale="0.01 0.01 0.01"/>
        </geometry>
        <material name="black">
        <color rgba="0 0 0 1"/>
        </material>
    </visual>
    <collision>
        <origin xyz="-0.305 1.2275 0" rpy="1.5708 0 0"/>
        <geometry>
        <mesh filename="package://auto_quad_description/meshes/propeller.stl" scale="0.01 0.01 0.01"/>
        </geometry>
    </collision>
    </link>

    <joint name="front_left_propeller_joint" type="continuous">
    <parent link="front_left_motor"/>
    <child link="front_left_propeller"/>
    <origin xyz="0 0 0.3" rpy="0 0 0"/> <!-- Adjust xyz for position -->
    <axis xyz="0 0 1"/> <!-- Rotate around the Z axis -->
    </joint>

    <!-- Front Right Propeller -->
    <link name="front_right_propeller">
    <visual>
        <origin xyz="-0.305 1.2275 0" rpy="1.5708 0 0"/>
        <geometry>
        <mesh filename="package://auto_quad_description/meshes/propeller.stl" scale="0.01 0.01 0.01"/>
        </geometry>
        <material name="black">
        <color rgba="0 0 0 1"/>
        </material>
    </visual>
    <collision>
        <origin xyz="-0.305 1.2275 0" rpy="1.5708 0 0"/>
        <geometry>
        <mesh filename="package://auto_quad_description/meshes/propeller.stl" scale="0.01 0.01 0.01"/>
        </geometry>
    </collision>
    </link>

    <joint name="front_right_propeller_joint" type="continuous">
    <parent link="front_right_motor"/>
    <child link="front_right_propeller"/>
    <origin xyz="0 0 0.3" rpy="0 0 0"/> <!-- Adjust xyz for position -->
    <axis xyz="0 0 1"/> <!-- Rotate around the Z axis -->
    </joint>


    <!-- Back Left Propeller -->
    <link name="back_left_propeller">
    <visual>
        <origin xyz="-0.305 1.2275 0" rpy="1.5708 0 0"/>
        <geometry>
        <mesh filename="package://auto_quad_description/meshes/propeller.stl" scale="0.01 0.01 0.01"/>
        </geometry>
        <material name="black">
        <color rgba="0 0 0 1"/>
        </material>
    </visual>
    <collision>
        <origin xyz="-0.305 1.2275 0" rpy="1.5708 0 0"/>
        <geometry>
        <mesh filename="package://auto_quad_description/meshes/propeller.stl" scale="0.01 0.01 0.01"/>
        </geometry>
    </collision>
    </link>

    <joint name="back_left_propeller_joint" type="continuous">
    <parent link="back_left_motor"/>
    <child link="back_left_propeller"/>
    <origin xyz="0 0 0.3" rpy="0 0 0"/> <!-- Adjust xyz for position -->
    <axis xyz="0 0 1"/> <!-- Rotate around the Z axis -->
    </joint>

    <!-- Back Right Propeller -->
    <link name="back_right_propeller">
    <visual>
        <origin xyz="-0.305 1.2275 0" rpy="1.5708 0 0"/>
        <geometry>
        <mesh filename="package://auto_quad_description/meshes/propeller.stl" scale="0.01 0.01 0.01"/>
        </geometry>
        <material name="black">
        <color rgba="0 0 0 1"/>
        </material>
    </visual>
    <collision>
        <origin xyz="-0.305 1.2275 0" rpy="1.5708 0 0"/>
        <geometry>
        <mesh filename="package://auto_quad_description/meshes/propeller.stl" scale="0.01 0.01 0.01"/>
        </geometry>
    </collision>
    </link>

    <joint name="back_right_propeller_joint" type="continuous">
    <parent link="back_right_motor"/>
    <child link="back_right_propeller"/>
    <origin xyz="0 0 0.3" rpy="0 0 0"/> <!-- Adjust xyz for position -->
    <axis xyz="0 0 1"/> <!-- Rotate around the Z axis -->
    </joint>

    <!-- ################################################################################
         #################################### PI Case ###################################
         ################################################################################ -->

    <link name="pi_case">
    <visual>
        <origin xyz="0 0 0" rpy="0 0 -1.5708"/>
        <geometry>
        <mesh filename="package://auto_quad_description/meshes/pi_case.stl" scale="0.01 0.01 0.01"/>
        </geometry>
        <material name="silver">
        <color rgba="0.8 0.8 0.8 1"/>
        </material>
    </visual>
    <collision>
        <origin xyz="0 0 0" rpy="0 0 -1.5708"/>
        <geometry>
        <mesh filename="package://auto_quad_description/meshes/pi_case.stl" scale="0.01 0.01 0.01"/>
        </geometry>
    </collision>
    </link>

    <joint name="pi_case_joint" type="fixed">
    <parent link="base_link"/>
    <child link="pi_case"/>
    <origin xyz="-0.49 0.5 0.21" rpy="0 0 0"/> <!-- Adjust xyz for position -->
    </joint>

    <!-- ################################################################################
         #################################### LIDAR #####################################
         ################################################################################ -->

    <link name="lidar_link">
    <visual>
        <origin xyz="0 0 0" rpy="0 0 0"/>
        <geometry>
        <mesh filename="package://auto_quad_description/meshes/laser_link.stl" scale="0.01 0.01 0.01"/>
        </geometry>
        <material name="black">
        <color rgba="0 0 0 1"/> <!-- Black color -->
        </material>
    </visual>
    <collision>
        <geometry>
            <mesh filename="package://auto_quad_description/meshes/laser_link.stl" scale="0.01 0.01 0.01"/>
        </geometry>
    </collision>
    </link>

    <joint name="lidar_joint" type="fixed">
    <parent link="base_link"/> <!-- Parent link (e.g., the robot's base) -->
    <child link="lidar_link"/> <!-- Child link (the LiDAR) -->
    <origin xyz="-0.18 0.05 0.51" rpy="0 0 0"/> <!-- Position the LiDAR 0.2m above the base -->
    <!-- <origin xyz="0.3 -0.48 0.32" rpy="0 0 0"/> -->
    </joint>


    <!-- ################################################################################
         ################################# Cameras ######################################
         ################################################################################ -->

    <link name="stereo_camera_link">
    <visual>
        <origin xyz="0 0 0" rpy="0 0 0"/>
        <geometry>
            <mesh filename="package://auto_quad_description/meshes/3d_stereo_camera.stl" scale="0.01 0.01 0.01"/>
        </geometry>
        <material name="black">
            <color rgba="0 0 0 1"/> <!-- Black color -->
        </material>
    </visual>
    <collision>
        <geometry>
            <mesh filename="package://auto_quad_description/meshes/3d_stereo_camera.stl" scale="0.01 0.01 0.01"/>
        </geometry>
    </collision>
    </link>

    <joint name="stereo_camera_joint" type="fixed">
    <parent link="base_link"/> <!-- Parent link (e.g., the robot's base) -->
    <child link="stereo_camera_link"/> <!-- Child link (the stereo camera) -->
    <origin xyz="0.35 0 0.25" rpy="1.5708 0 1.5708"/> <!-- Position the camera 0.2m forward and 0.3m above the base -->
    </joint>    

</robot>
